Workbook

Sheet Factsheet_Fund_Key
A1: as_of | B1: amc | C1: fund_key | D1: asset_class | E1: category | F1: monthly_avg_aum_cr | G1: ter_direct_pct | H1: portfolio_turnover | I1: Fund_Manager | J1: Fund_Manager_experience | K1: Notes
A2: 46022 | B2: Aditya Birla Sun Life Mutual Fund | C2: ABSL_ELSS | D2: =_xlfn.XLOOKUP(C2,mfscreener.portfolio_holdings_v!$C:$C,mfscreener.portfolio_holdings_v!$E:$E) -> ELSS | E2: =_xlfn.XLOOKUP(C2,mfscreener.portfolio_holdings_v!$C:$C,mfscreener.portfolio_holdings_v!$D:$D) -> Equity | F2: 15615.09 | G2: 0.95 | H2: 0.35 | I2: Dhaval Shah | J2: 20
A3: 46022 | B3: Aditya Birla Sun Life Mutual Fund | C3: ABSL_FLEXI_CAP | D3: =_xlfn.XLOOKUP(C3,mfscreener.portfolio_holdings_v!$C:$C,mfscreener.portfolio_holdings_v!$E:$E) -> Flexi Cap | E3: =_xlfn.XLOOKUP(C3,mfscreener.portfolio_holdings_v!$C:$C,mfscreener.portfolio_holdings_v!$D:$D) -> Equity | F3: 24596.21 | G3: 0.32 | H3: 0.86 | I3: Harish Krishnan,Dhaval Joshi | J3: 21,18
A4: 46022 | B4: Aditya Birla Sun Life Mutual Fund | C4: ABSL_FOCUSED | D4: =_xlfn.XLOOKUP(C4,mfscreener.portfolio_holdings_v!$C:$C,mfscreener.portfolio_holdings_v!$E:$E) -> Focused | E4: =_xlfn.XLOOKUP(C4,mfscreener.portfolio_holdings_v!$C:$C,mfscreener.portfolio_holdings_v!$D:$D) -> Equity | F4: 8112.67 | G4: 0.3 | H4: 0.88 | I4: Kunal Sangoi | J4: 20
A5: 46022 | B5: Aditya Birla Sun Life Mutual Fund | C5: ABSL_LARGE_CAP | D5: =_xlfn.XLOOKUP(C5,mfscreener.portfolio_holdings_v!$C:$C,mfscreener.portfolio_holdings_v!$E:$E) -> Large Cap | E5: =_xlfn.XLOOKUP(C5,mfscreener.portfolio_holdings_v!$C:$C,mfscreener.portfolio_holdings_v!$D:$D) -> Equity | F5: 31160.13 | G5: 0.55 | H5: 0.97 | I5: Mahesh Patil | J5: 31
A6: 46022 | B6: Aditya Birla Sun Life Mutual Fund | C6: ABSL_LARGE_MID_CAP | D6: =_xlfn.XLOOKUP(C6,mfscreener.portfolio_holdings_v!$C:$C,mfscreener.portfolio_holdings_v!$E:$E) -> Large & Mid Cap | E6: =_xlfn.XLOOKUP(C6,mfscreener.portfolio_holdings_v!$C:$C,mfscreener.portfolio_holdings_v!$D:$D) -> Equity | F6: 5842.88 | G6: 0.59 | H6: 1.08 | I6: Vishal Gajwani | J6: 19
A7: 46022 | B7: Aditya Birla Sun Life Mutual Fund | C7: ABSL_MID_CAP | D7: =_xlfn.XLOOKUP(C7,mfscreener.portfolio_holdings_v!$C:$C,mfscreener.portfolio_holdings_v!$E:$E) -> Mid Cap | E7: =_xlfn.XLOOKUP(C7,mfscreener.portfolio_holdings_v!$C:$C,mfscreener.portfolio_holdings_v!$D:$D) -> Equity | F7: 6267.84 | G7: 0.85 | H7: 1.02 | I7: Mr. Chanchal Khandelwal | J7: 15
A8: 46022 | B8: Aditya Birla Sun Life Mutual Fund | C8: ABSL_MULTI_CAP | D8: =_xlfn.XLOOKUP(C8,mfscreener.portfolio_holdings_v!$C:$C,mfscreener.portfolio_holdings_v!$E:$E) -> Multi Cap | E8: =_xlfn.XLOOKUP(C8,mfscreener.portfolio_holdings_v!$C:$C,mfscreener.portfolio_holdings_v!$D:$D) -> Equity | F8: 6752.33 | G8: 0.63 | H8: 0.75 | I8: Abhinav Khandelwal,Harshil Suvarnkar | J8: 15,15
A9: 46022 | B9: Aditya Birla Sun Life Mutual Fund | C9: ABSL_SMALL_CAP | D9: =_xlfn.XLOOKUP(C9,mfscreener.portfolio_holdings_v!$C:$C,mfscreener.portfolio_holdings_v!$E:$E) -> Small Cap | E9: =_xlfn.XLOOKUP(C9,mfscreener.portfolio_holdings_v!$C:$C,mfscreener.portfolio_holdings_v!$D:$D) -> Equity | F9: 5097.16 | G9: 0.51 | H9: 0.9 | I9: Abhinav Khandelwal,Dhaval Joshi | J9: 15,18
A10: 46022 | B10: Aditya Birla Sun Life Mutual Fund | C10: ABSL_VALUE | D10: =_xlfn.XLOOKUP(C10,mfscreener.portfolio_holdings_v!$C:$C,mfscreener.portfolio_holdings_v!$E:$E) -> Value | E10: =_xlfn.XLOOKUP(C10,mfscreener.portfolio_holdings_v!$C:$C,mfscreener.portfolio_holdings_v!$D:$D) -> Equity | F10: 6338.33 | G10: 0.72 | H10: 1.02 | I10: Kunal Sangoi | J10: 20
A11: 46022 | B11: Aditya Birla Sun Life Mutual Fund | C11: ABSL_BANKING_FINANCIAL | D11: =_xlfn.XLOOKUP(C11,mfscreener.portfolio_holdings_v!$C:$C,mfscreener.portfolio_holdings_v!$E:$E) -> Banking & Financial Services | E11: =_xlfn.XLOOKUP(C11,mfscreener.portfolio_holdings_v!$C:$C,mfscreener.portfolio_holdings_v!$D:$D) -> Equity | F11: 3660.74 | G11: 0.99 | H11: 0.34 | I11: Dhaval Gala | J11: 19
A12: 46022 | B12: Aditya Birla Sun Life Mutual Fund | C12: ABSL_MANUFACTURING | D12: Manufacturing | E12: =_xlfn.XLOOKUP(C12,mfscreener.portfolio_holdings_v!$C:$C,mfscreener.portfolio_holdings_v!$D:$D) -> Equity | F12: 1107.08 | G12: 1.34 | H12: 0.31 | I12: Harish Krishnan | J12: 15
A13: 46022 | B13: Aditya Birla Sun Life Mutual Fund | C13: ABSL_PSU_EQUITY | D13: =_xlfn.XLOOKUP(C13,mfscreener.portfolio_holdings_v!$C:$C,mfscreener.portfolio_holdings_v!$E:$E) -> PSU Equity | E13: =_xlfn.XLOOKUP(C13,mfscreener.portfolio_holdings_v!$C:$C,mfscreener.portfolio_holdings_v!$D:$D) -> Equity | F13: 5680.9 | G13: 0.61 | H13: 0.24 | I13: Dhaval Gala | J13: 19
A14: 46022 | B14: Aditya Birla Sun Life Mutual Fund | C14: ABSL_PHARMA_HEALTHCARE | D14: Healthcare | E14: =_xlfn.XLOOKUP(C14,mfscreener.portfolio_holdings_v!$C:$C,mfscreener.portfolio_holdings_v!$D:$D) -> Equity | F14: 850.88 | G14: 1.02 | H14: 0.31 | I14: Mr. Dhaval Shah | J14: 20
A15: 46022 | B15: Aditya Birla Sun Life Mutual Fund | C15: ABSL_DIGITAL_INDIA | D15: Technology | E15: =_xlfn.XLOOKUP(C15,mfscreener.portfolio_holdings_v!$C:$C,mfscreener.portfolio_holdings_v!$D:$D) -> Equity | F15: 4788.07 | G15: 0.79 | H15: 0.48 | I15: Kunal Sangoi | J15: 20
A16: 46022 | B16: Aditya Birla Sun Life Mutual Fund | C16: ABSL_CONGLOMERATE | D16: =_xlfn.XLOOKUP(C16,mfscreener.portfolio_holdings_v!$C:$C,mfscreener.portfolio_holdings_v!$E:$E) -> Conglomerate | E16: =_xlfn.XLOOKUP(C16,mfscreener.portfolio_holdings_v!$C:$C,mfscreener.portfolio_holdings_v!$D:$D) -> Equity | F16: 1763.06 | G16: 0.7 | I16: Harish Krishnan , Kunal Sangoi | J16: 15,20
A17: 46022 | B17: Aditya Birla Sun Life Mutual Fund | C17: ABSL_BUSINESS_CYCLE | D17: =_xlfn.XLOOKUP(C17,mfscreener.portfolio_holdings_v!$C:$C,mfscreener.portfolio_holdings_v!$E:$E) -> Business Cycle | E17: =_xlfn.XLOOKUP(C17,mfscreener.portfolio_holdings_v!$C:$C,mfscreener.portfolio_holdings_v!$D:$D) -> Equity | F17: 1796.68 | G17: 1.15 | H17: 0.36 | I17: Harish Krishnan, dhaval gala | J17: 15 , 19
A18: 46022 | B18: Aditya Birla Sun Life Mutual Fund | C18: ABSL_INFRASTRUCTURE | D18: =_xlfn.XLOOKUP(C18,mfscreener.portfolio_holdings_v!$C:$C,mfscreener.portfolio_holdings_v!$E:$E) -> Infrastructure | E18: =_xlfn.XLOOKUP(C18,mfscreener.portfolio_holdings_v!$C:$C,mfscreener.portfolio_holdings_v!$D:$D) -> Equity | F18: 1145.24 | G18: 1.42 | H18: 0.44 | I18: Mr. Mahesh Patil ,Mr. Jonas Bhutta | J18: 31
A19: 46022 | B19: Aditya Birla Sun Life Mutual Fund | C19: ABSL_TRANSPORT_LOGISTICS | D19: =_xlfn.XLOOKUP(C19,mfscreener.portfolio_holdings_v!$C:$C,mfscreener.portfolio_holdings_v!$E:$E) -> Transportation & Logistics | E19: =_xlfn.XLOOKUP(C19,mfscreener.portfolio_holdings_v!$C:$C,mfscreener.portfolio_holdings_v!$D:$D) -> Equity | F19: 1595.14 | G19: 0.78 | H19: 0.14 | I19: Dhaval Gala | J19: 19
A20: 46022 | B20: Aditya Birla Sun Life Mutual Fund | C20: ABSL_MNC | D20: =_xlfn.XLOOKUP(C20,mfscreener.portfolio_holdings_v!$C:$C,mfscreener.portfolio_holdings_v!$E:$E) -> MNC | E20: =_xlfn.XLOOKUP(C20,mfscreener.portfolio_holdings_v!$C:$C,mfscreener.portfolio_holdings_v!$D:$D) -> Equity | F20: 3659.55 | G20: 1.3 | H20: 0.2 | I20: Chanchal Khandelwal | J20: 15
A21: 46022 | B21: Aditya Birla Sun Life Mutual Fund | C21: ABSL_QUANT | D21: =_xlfn.XLOOKUP(C21,mfscreener.portfolio_holdings_v!$C:$C,mfscreener.portfolio_holdings_v!$E:$E) -> Quant | E21: =_xlfn.XLOOKUP(C21,mfscreener.portfolio_holdings_v!$C:$C,mfscreener.portfolio_holdings_v!$D:$D) -> Equity | F21: 2362.84 | G21: 0.65 | I21: Harish Krishnan | J21: 15
A22: 46022 | B22: Aditya Birla Sun Life Mutual Fund | C22: ABSL_BALANCED_ADVANTAGE | D22: =_xlfn.XLOOKUP(C22,mfscreener.portfolio_holdings_v!$C:$C,mfscreener.portfolio_holdings_v!$E:$E) -> Balanced Advantage | E22: =_xlfn.XLOOKUP(C22,mfscreener.portfolio_holdings_v!$C:$C,mfscreener.portfolio_holdings_v!$D:$D) -> Hybrid | F22: 8688.64 | G22: 0.67 | H22: 2.44 | I22: Mohit Sharma, Mr. Lovelish Solanki ,Mr. Harish Krishnan | J22: ,10 , 21
A23: 46022 | B23: Aditya Birla Sun Life Mutual Fund | C23: ABSL_MULTI_ASSET | D23: =_xlfn.XLOOKUP(C23,mfscreener.portfolio_holdings_v!$C:$C,mfscreener.portfolio_holdings_v!$E:$E) -> Multi Asset Allocation | E23: =_xlfn.XLOOKUP(C23,mfscreener.portfolio_holdings_v!$C:$C,mfscreener.portfolio_holdings_v!$D:$D) -> Hybrid | F23: 5068.21 | G23: 0.59 | H23: 0.57 | I23: Mr. Dhaval Gala, Mr. Bhupesh Bameta ,Mr. Sachin Wankhede | J23: 19, 17, 23
A24: 46022 | B24: Aditya Birla Sun Life Mutual Fund | C24: ABSL_EQUITY_HYBRID_95 | D24: =_xlfn.XLOOKUP(C24,mfscreener.portfolio_holdings_v!$C:$C,mfscreener.portfolio_holdings_v!$E:$E) -> Equity Hybrid 95 | E24: =_xlfn.XLOOKUP(C24,mfscreener.portfolio_holdings_v!$C:$C,mfscreener.portfolio_holdings_v!$D:$D) -> Hybrid | F24: 7563.45 | G24: 1.09 | H24: 0.55 | I24: mr. Harshil Suvarnkar ,Mr. Chanchal Khandelwal | J24: 15,15
A25: 46022 | B25: Aditya Birla Sun Life Mutual Fund | C25: ABSL_EQUITY_SAVINGS | D25: =_xlfn.XLOOKUP(C25,mfscreener.portfolio_holdings_v!$C:$C,mfscreener.portfolio_holdings_v!$E:$E) -> Equity Savings | E25: =_xlfn.XLOOKUP(C25,mfscreener.portfolio_holdings_v!$C:$C,mfscreener.portfolio_holdings_v!$D:$D) -> Hybrid | F25: 943.21 | G25: 0.53 | H25: 6.83 | I25: Atul Penkar, Mr. Harshil Suvarnkar & Mr. Lovelish Solanki | J25: 25, 15 , 10
A26: 46022 | B26: Aditya Birla Sun Life Mutual Fund | C26: ABSL_REGULAR_SAVINGS | D26: =_xlfn.XLOOKUP(C26,mfscreener.portfolio_holdings_v!$C:$C,mfscreener.portfolio_holdings_v!$E:$E) -> Regular Savings | E26: =_xlfn.XLOOKUP(C26,mfscreener.portfolio_holdings_v!$C:$C,mfscreener.portfolio_holdings_v!$D:$D) -> Hybrid | F26: 1552.73 | G26: 0.93 | H26: 1.18
A27: 46022 | B27: 360 ONE Mutual Fund | C27: ONE360_BALANCED_HYBRID | D27: =_xlfn.XLOOKUP(C27,mfscreener.portfolio_holdings_v!$C:$C,mfscreener.portfolio_holdings_v!$E:$E) -> Balanced Hybrid | E27: =_xlfn.XLOOKUP(C27,mfscreener.portfolio_holdings_v!$C:$C,mfscreener.portfolio_holdings_v!$D:$D) -> Hybrid | F27: 841.6 | G27: 0.45 | H27: 0.55 | I27: Mr. Mayur Patel, Mr. Milan Mody | J27: 20,20
A28: 46022 | B28: 360 ONE Mutual Fund | C28: ONE360_FLEXI_CAP | D28: =_xlfn.XLOOKUP(C28,mfscreener.portfolio_holdings_v!$C:$C,mfscreener.portfolio_holdings_v!$E:$E) -> Flexi Cap | E28: =_xlfn.XLOOKUP(C28,mfscreener.portfolio_holdings_v!$C:$C,mfscreener.portfolio_holdings_v!$D:$D) -> Equity | F28: 2087.06 | G28: 0.48 | H28: 0.43 | I28: Mr. Mayur Patel | J28: 20
A29: 46022 | B29: 360 ONE Mutual Fund | C29: ONE360_FOCUSED | D29: =_xlfn.XLOOKUP(C29,mfscreener.portfolio_holdings_v!$C:$C,mfscreener.portfolio_holdings_v!$E:$E) -> Focused | E29: =_xlfn.XLOOKUP(C29,mfscreener.portfolio_holdings_v!$C:$C,mfscreener.portfolio_holdings_v!$D:$D) -> Equity | F29: 7229.59 | G29: 0.81 | H29: 0.42 | I29: Mr. Mayur Patel | J29: 20
A30: 46022 | B30: 360 ONE Mutual Fund | C30: ONE360_QUANT | D30: =_xlfn.XLOOKUP(C30,mfscreener.portfolio_holdings_v!$C:$C,mfscreener.portfolio_holdings_v!$E:$E) -> Quant | E30: =_xlfn.XLOOKUP(C30,mfscreener.portfolio_holdings_v!$C:$C,mfscreener.portfolio_holdings_v!$D:$D) -> Equity | F30: 893.6 | G30: 0.62 | H30: 1.1 | I30: Mr. Ashish Ongari | J30: 6
A31: 46022 | B31: Axis Mutual Fund | C31: AXIS_ELSS | D31: =_xlfn.XLOOKUP(C31,mfscreener.portfolio_holdings_v!$C:$C,mfscreener.portfolio_holdings_v!$E:$E) -> ELSS | E31: =_xlfn.XLOOKUP(C31,mfscreener.portfolio_holdings_v!$C:$C,mfscreener.portfolio_holdings_v!$D:$D) -> Equity | F31: 34449.51 | G31: 0.81 | H31: 0.25 | I31: Mr. Shreyash Devalkar, Mr. Ashish Naik | J31: 21,17
A32: 46022 | B32: Axis Mutual Fund | C32: AXIS_FLEXI_CAP | D32: =_xlfn.XLOOKUP(C32,mfscreener.portfolio_holdings_v!$C:$C,mfscreener.portfolio_holdings_v!$E:$E) -> Flexi Cap | E32: =_xlfn.XLOOKUP(C32,mfscreener.portfolio_holdings_v!$C:$C,mfscreener.portfolio_holdings_v!$D:$D) -> Equity | F32: 13090.34 | G32: 0.72 | H32: 0.18 | I32: Mr. Sachin Relekar, Ms. Krishnaa N | J32: 24,5
A33: 46022 | B33: Axis Mutual Fund | C33: AXIS_FOCUSED | D33: =_xlfn.XLOOKUP(C33,mfscreener.portfolio_holdings_v!$C:$C,mfscreener.portfolio_holdings_v!$E:$E) -> Focused | E33: =_xlfn.XLOOKUP(C33,mfscreener.portfolio_holdings_v!$C:$C,mfscreener.portfolio_holdings_v!$D:$D) -> Equity | F33: 12149.35 | G33: 0.84 | H33: 0.21 | I33: Mr. Sachin Relekar, Ms. Krishnaa N | J33: 24,5
A34: 46022 | B34: Axis Mutual Fund | C34: AXIS_LARGE_CAP | D34: =_xlfn.XLOOKUP(C34,mfscreener.portfolio_holdings_v!$C:$C,mfscreener.portfolio_holdings_v!$E:$E) -> Large Cap | E34: =_xlfn.XLOOKUP(C34,mfscreener.portfolio_holdings_v!$C:$C,mfscreener.portfolio_holdings_v!$D:$D) -> Equity | F34: 33618.06 | G34: 0.72 | H34: 0.86 | I34: Mr. Shreyash Devalkar, Mr. Jayesh Sundar ,Ms. Krishnaa N | J34: 21,22,5
A35: 46022 | B35: Axis Mutual Fund | C35: AXIS_LARGE_MID_CAP | D35: =_xlfn.XLOOKUP(C35,mfscreener.portfolio_holdings_v!$C:$C,mfscreener.portfolio_holdings_v!$E:$E) -> Large & Mid Cap | E35: =_xlfn.XLOOKUP(C35,mfscreener.portfolio_holdings_v!$C:$C,mfscreener.portfolio_holdings_v!$D:$D) -> Equity | F35: 15508.91 | G35: 0.59 | H35: 0.61 | I35: Mr. Shreyash Devalkar ,Mr. Hitesh Das, Ms. Krishnaa N | J35: 21,14,5
A36: 46022 | B36: Axis Mutual Fund | C36: AXIS_MID_CAP | D36: =_xlfn.XLOOKUP(C36,mfscreener.portfolio_holdings_v!$C:$C,mfscreener.portfolio_holdings_v!$E:$E) -> Mid Cap | E36: =_xlfn.XLOOKUP(C36,mfscreener.portfolio_holdings_v!$C:$C,mfscreener.portfolio_holdings_v!$D:$D) -> Equity | F36: 31710.81 | G36: 0.55 | H36: 0.43 | I36: Mr. Shreyash Devalkar ,Mr. Hitesh Das, Ms. Krishnaa N | J36: 21,14,5
A37: 46022 | B37: Axis Mutual Fund | C37: AXIS_MULTI_CAP | D37: =_xlfn.XLOOKUP(C37,mfscreener.portfolio_holdings_v!$C:$C,mfscreener.portfolio_holdings_v!$E:$E) -> Multi Cap | E37: =_xlfn.XLOOKUP(C37,mfscreener.portfolio_holdings_v!$C:$C,mfscreener.portfolio_holdings_v!$D:$D) -> Equity | F37: 9185.27 | G37: 0.72 | H37: 0.45 | I37: Mr. Nitin Arora ,Mr. Shreyash Devalkar, Mr. Hitesh Das | J37: 14,21,14
A38: 46022 | B38: Axis Mutual Fund | C38: AXIS_SMALL_CAP | D38: =_xlfn.XLOOKUP(C38,mfscreener.portfolio_holdings_v!$C:$C,mfscreener.portfolio_holdings_v!$E:$E) -> Small Cap | E38: =_xlfn.XLOOKUP(C38,mfscreener.portfolio_holdings_v!$C:$C,mfscreener.portfolio_holdings_v!$D:$D) -> Equity | F38: 26486.45 | G38: 0.57 | H38: 0.34 | I38: Mr. Tejas Sheth, Mr. Mayank Hyanki , Ms. Krishnaa N | J38: 21,15 ,5
A39: 46022 | B39: Axis Mutual Fund | C39: AXIS_VALUE | D39: =_xlfn.XLOOKUP(C39,mfscreener.portfolio_holdings_v!$C:$C,mfscreener.portfolio_holdings_v!$E:$E) -> Value | E39: =_xlfn.XLOOKUP(C39,mfscreener.portfolio_holdings_v!$C:$C,mfscreener.portfolio_holdings_v!$D:$D) -> Equity | F39: 1299.23 | G39: 0.73 | H39: 0.41 | I39: Mr. Nitin Arora, Ms. Krishnaa N | J39: 24,5
A40: 46022 | B40: Axis Mutual Fund | C40: AXIS_INNOVATION | D40: =_xlfn.XLOOKUP(C40,mfscreener.portfolio_holdings_v!$C:$C,mfscreener.portfolio_holdings_v!$E:$E) -> Thematic | E40: =_xlfn.XLOOKUP(C40,mfscreener.portfolio_holdings_v!$C:$C,mfscreener.portfolio_holdings_v!$D:$D) -> Equity | F40: 1195.08 | G40: 1.29 | H40: 0.71 | I40: Mr. Ashish Naik , Ms. Krishnaa N | J40: 17 , 5
...

Sheet mfscreener.portfolio_holdings_v
A1: as_of | B1: amc | C1: fund_key | D1: asset_class | E1: category
A2: 46022 | B2: Aditya Birla Sun Life Mutual Fund | C2: ABSL_LARGE_CAP | D2: Equity | E2: Large Cap
A3: 46022 | B3: Aditya Birla Sun Life Mutual Fund | C3: ABSL_LARGE_MID_CAP | D3: Equity | E3: Large & Mid Cap
A4: 46022 | B4: Aditya Birla Sun Life Mutual Fund | C4: ABSL_MID_CAP | D4: Equity | E4: Mid Cap
A5: 46022 | B5: Aditya Birla Sun Life Mutual Fund | C5: ABSL_SMALL_CAP | D5: Equity | E5: Small Cap
A6: 46022 | B6: Aditya Birla Sun Life Mutual Fund | C6: ABSL_FLEXI_CAP | D6: Equity | E6: Flexi Cap
A7: 46022 | B7: Aditya Birla Sun Life Mutual Fund | C7: ABSL_MULTI_CAP | D7: Equity | E7: Multi Cap
A8: 46022 | B8: Aditya Birla Sun Life Mutual Fund | C8: ABSL_VALUE | D8: Equity | E8: Value
A9: 46022 | B9: Aditya Birla Sun Life Mutual Fund | C9: ABSL_ELSS | D9: Equity | E9: ELSS
A10: 46022 | B10: Aditya Birla Sun Life Mutual Fund | C10: ABSL_FOCUSED | D10: Equity | E10: Focused
A11: 46022 | B11: Aditya Birla Sun Life Mutual Fund | C11: ABSL_BANKING_FINANCIAL | D11: Equity | E11: Banking & Financial Services
A12: 46022 | B12: Aditya Birla Sun Life Mutual Fund | C12: ABSL_MANUFACTURING | D12: Equity | E12: Manufacturing Equity
A13: 46022 | B13: Aditya Birla Sun Life Mutual Fund | C13: ABSL_PSU_EQUITY | D13: Equity | E13: PSU Equity
... A672: 46022 | B672: UTI Mutual Fund | C672: UTI_MULTI_ASSET | D672: Hybrid | E672: Multi Asset
